<?xml version="1.0" ?>
<sdf version="1.6">
<world name="default">
<include>
<uri> model://ground_plane</uri>
</include>
<physics name='phy' type='ode'>
  <ode>
    <solver>
      <type>quick</type>
      <iters>30</iters>
    </solver>
    </ode>
</physics>

<model name="track_creator">
 <pose frame=''>0 0 0 0 0 0</pose>   
<link name="base_link">
      <self_collide>0</self_collide>
      <pose>0 0 0.14 0 0 0</pose>
      <collision name="base_link_collision">
        <geometry>
          <box>
            <size>0.56 0.34 0.14</size>
          </box>
        </geometry>
      </collision>
      <visual name="base_link_visual">
        <geometry>
          <box>
            <size>0.56 0.34 0.14</size>
          </box>
        </geometry>
      </visual>
    </link>
    <link name="drum1">
      <self_collide>1</self_collide>
      <pose>0.28 0.22 0.071 1.57079632679 0 0</pose>
      <collision name="drum1_collision">
        <geometry>
          <!--cylinder>
            <radius>0.07</radius>
            <length>0.1</length>
          </cylinder-->
        <mesh>
         <uri>
           file:///home/shankar/simu_ws/src/uhugv/wheel.stl 
         </uri>
        </mesh>
        </geometry>
      </collision>

      <visual name="drum1_visual">
        <material> <!-- Wheel material -->
          <ambient>0 0 0 1</ambient>
          <diffuse>0.1 0.1 0.1 1</diffuse>
          <specular>0 0 0 0</specular>
          <emissive>0 0 0 1</emissive>
        </material>
        <geometry>
        <mesh>
         <uri>
           file:///home/shankar/simu_ws/src/uhugv/wheel.stl 
         </uri>
        </mesh>
        </geometry>
      </visual>
    </link>
    <joint type="revolute" name="drum_joint1">
      <pose>0 0 0 0 0 0</pose>
      <parent>base_link</parent>
      <child>drum1</child>
      <axis>
        <xyz>0 0 -1</xyz>       
      </axis>
    </joint>
    <link name="drum2">
      <self_collide>1</self_collide>
      <pose>0.28 -0.22 0.071 1.57079632679 0 0</pose>
      <collision name="drum2_collision">
        <geometry>
       <mesh>
         <uri>
           file:///home/shankar/simu_ws/src/uhugv/wheel2.stl 
         </uri>
        </mesh>
        </geometry>
      </collision>
	<friction>
          <ode>
            <mu>1</mu>
            <mu2>1</mu2>
          </ode>
        </friction>
      <visual name="drum2_visual">
                <material> <!-- Wheel material -->
          <ambient>0 0 0 1</ambient>
          <diffuse>0.1 0.1 0.1 1</diffuse>
          <specular>0 0 0 0</specular>
          <emissive>0 0 0 1</emissive>
        </material>
        <geometry>
       <mesh>
         <uri>
           file:///home/shankar/simu_ws/src/uhugv/wheel2.stl 
         </uri>
        </mesh>
        </geometry>
      </visual>
    </link>
    <joint type="revolute" name="drum_joint2">
      <pose>0 0 0 0 0 0</pose>
      <parent>base_link</parent>
      <child>drum2</child>
      <axis>
        <xyz>0 0 -1</xyz>
      </axis>
    </joint>
    <link name="drum3">
      <self_collide>1</self_collide>
      <pose>-0.28 0.22 0.071 1.57079632679 0 0</pose>
      <collision name="drum3_collision">
        <geometry>
       <mesh>
         <uri>
           file:///home/shankar/simu_ws/src/uhugv/wheel.stl 
         </uri>
        </mesh>
        </geometry>
      </collision>
	<surface>	
	<friction>
          <ode>
            <mu>1</mu>
            <mu2>1</mu2>
          </ode>
        </friction>
	</surface>
      <visual name="drum3_visual">
                <material> <!-- Wheel material -->
          <ambient>0 0 0 1</ambient>
          <diffuse>0.1 0.1 0.1 1</diffuse>
          <specular>0 0 0 0</specular>
          <emissive>0 0 0 1</emissive>
        </material>
        <geometry>
       <mesh>
         <uri>
           file:///home/shankar/simu_ws/src/uhugv/wheel.stl 
         </uri>
        </mesh>
        </geometry>
      </visual>
    </link>
    <joint type="revolute" name="drum_joint3">
      <pose>0 0 0 0 0 0</pose>
      <parent>base_link</parent>
      <child>drum3</child>
      <axis>
        <xyz>0 0 -1</xyz>
      </axis>
    </joint>
    <link name="drum4">
      <self_collide>1</self_collide>
      <pose>-0.28 -0.22 0.071 1.57079632679 0 0</pose>
      <collision name="drum4_collision">
        <geometry>
       <mesh>
         <uri>
           file:///home/shankar/simu_ws/src/uhugv/wheel2.stl 
         </uri>
        </mesh>
        </geometry>
      </collision>
	<surface>	
	<friction>
          <ode>
            <mu>1</mu>
            <mu2>1</mu2>
          </ode>
        </friction>
	</surface>
      <visual name="drum4_visual">
                <material> <!-- Wheel material -->
          <ambient>0 0 0 1</ambient>
          <diffuse>0.1 0.1 0.1 1</diffuse>
          <specular>0 0 0 0</specular>
          <emissive>0 0 0 1</emissive>
        </material>
        <geometry>
        <mesh>
         <uri>
           file:///home/shankar/simu_ws/src/uhugv/wheel2.stl 
         </uri>
        </mesh>
        </geometry>
      </visual>
    </link>
    <joint type="revolute" name="drum_joint4">
      <pose>0 0 0 0 0 0</pose>
      <parent>base_link</parent>
      <child>drum4</child>
      <axis>
        <xyz>0 0 -1</xyz>
      </axis>
    </joint>
    <link name="right_pad1">
      <self_collide>1</self_collide>
      <pose>0.1042 0.22000000000000003 0.0005 0 0.0 0</pose>
      <collision name="right_pad1_collision">
        <geometry>
        <mesh>
         <uri>
           file:///home/shankar/simu_ws/src/uhugv/track.stl 
         </uri>
        </mesh>
        </geometry>
      </collision>
      <visual name="right_pad1_visual">
        <geometry>
        <mesh>
         <uri>
           file:///home/shankar/simu_ws/src/uhugv/track.stl 
         </uri>
        </mesh>
        </geometry>
      </visual>
    </link>
    <joint name="right_pad_joint1" type="revolute">
      <pose>-0.0521 0 0 0 0 0</pose>
      <parent>right_pad1</parent>
      <child>right_pad2</child>
      <axis>
        <xyz>0 1 0</xyz>
      </axis>
    </joint>
    <link name="right_pad2">
      <self_collide>1</self_collide>
      <pose>0.2084 0.22000000000000003 0.0005 0 0.0 0</pose>
      <collision name="right_pad2_collision">
        <geometry>
        <mesh>
         <uri>
           file:///home/shankar/simu_ws/src/uhugv/track.stl 
         </uri>
        </mesh>
        </geometry>
      </collision>
      <visual name="right_pad2_visual">
        <geometry>
        <mesh>
         <uri>
           file:///home/shankar/simu_ws/src/uhugv/track.stl 
         </uri>
        </mesh>
        </geometry>
      </visual>
    </link>
    <joint name="right_pad_joint2" type="revolute">
      <pose>-0.0521 0 0 0 0 0</pose>
      <parent>right_pad2</parent>
      <child>right_pad3</child>
      <axis>
        <xyz>0 1 0</xyz>
      </axis>
    </joint>
    <link name="right_pad3">
      <self_collide>1</self_collide>
      <pose>0.3126 0.22000000000000003 0.0005 0 0.0 0</pose>
      <collision name="right_pad3_collision">
        <geometry>
        <mesh>
         <uri>
           file:///home/shankar/simu_ws/src/uhugv/track.stl 
         </uri>
        </mesh>
        </geometry>
      </collision>
      <visual name="right_pad3_visual">
        <geometry>
        <mesh>
         <uri>
           file:///home/shankar/simu_ws/src/uhugv/track.stl 
         </uri>
        </mesh>
        </geometry>
      </visual>
    </link>
    <joint name="right_pad_joint3" type="revolute">
      <pose>-0.0521 0 0 0 0 0</pose>
      <parent>right_pad3</parent>
      <child>right_pad4</child>
      <axis>
        <xyz>0 1 0</xyz>
      </axis>
    </joint>
    <link name="right_pad4">
      <self_collide>1</self_collide>
      <pose>0.39375294595031574 0.22000000000000003 0.04374738525746999 0 -0.979258607616 0</pose>
      <collision name="right_pad4_collision">
        <geometry>
        <mesh>
         <uri>
           file:///home/shankar/simu_ws/src/uhugv/track.stl 
         </uri>
        </mesh>
        </geometry>
      </collision>
      <visual name="right_pad4_visual">
        <geometry>
        <mesh>
         <uri>
           file:///home/shankar/simu_ws/src/uhugv/track.stl 
         </uri>
        </mesh>
        </geometry>
      </visual>
    </link>
    <joint name="right_pad_joint4" type="revolute">
      <pose>-0.0521 0 0 0 0 0</pose>
      <parent>right_pad4</parent>
      <child>right_pad5</child>
      <axis>
        <xyz>0 1 0</xyz>
      </axis>
    </joint>
    <link name="right_pad5">
      <self_collide>1</self_collide>
      <pose>0.4031079521076168 0.22000000000000003 0.13522755156590954 0 -1.95851721523 0</pose>
      <collision name="right_pad5_collision">
        <geometry>
        <mesh>
         <uri>
           file:///home/shankar/simu_ws/src/uhugv/track.stl 
         </uri>
        </mesh>
        </geometry>
      </collision>
      <visual name="right_pad5_visual">
        <geometry>
        <mesh>
         <uri>
           file:///home/shankar/simu_ws/src/uhugv/track.stl 
         </uri>
        </mesh>
        </geometry>
      </visual>
    </link>
    <joint name="right_pad_joint5" type="revolute">
      <pose>-0.0521 0 0 0 0 0</pose>
      <parent>right_pad5</parent>
      <child>right_pad6</child>
      <axis>
        <xyz>0 1 0</xyz>
      </axis>
    </joint>
    <link name="right_pad6">
      <self_collide>1</self_collide>
      <pose>0.3323884222130761 0.22000000000000003 0.19400582186640458 0 -2.93777582285 0</pose>
      <collision name="right_pad6_collision">
        <geometry>
        <mesh>
         <uri>
           file:///home/shankar/simu_ws/src/uhugv/track.stl 
         </uri>
        </mesh>
        </geometry>
      </collision>
      <visual name="right_pad6_visual">
        <geometry>
        <mesh>
         <uri>
           file:///home/shankar/simu_ws/src/uhugv/track.stl 
         </uri>
        </mesh>
        </geometry>
      </visual>
    </link>
    <joint name="right_pad_joint6" type="revolute">
      <pose>-0.0521 0 0 0 0 0</pose>
      <parent>right_pad6</parent>
      <child>right_pad7</child>
      <axis>
        <xyz>0 1 0</xyz>
      </axis>
    </joint>
    <link name="right_pad7">
      <self_collide>1</self_collide>
      <pose>0.22926683211155 0.22000000000000003 0.20455131111593003 0 3.14159265359 0</pose>
      <collision name="right_pad7_collision">
        <geometry>
        <mesh>
         <uri>
           file:///home/shankar/simu_ws/src/uhugv/track.stl 
         </uri>
        </mesh>
        </geometry>
      </collision>
      <visual name="right_pad7_visual">
        <geometry>
        <mesh>
         <uri>
           file:///home/shankar/simu_ws/src/uhugv/track.stl 
         </uri>
        </mesh>
        </geometry>
      </visual>
    </link>
    <joint name="right_pad_joint7" type="revolute">
      <pose>-0.0521 0 0 0 0 0</pose>
      <parent>right_pad7</parent>
      <child>right_pad8</child>
      <axis>
        <xyz>0 1 0</xyz>
      </axis>
    </joint>
    <link name="right_pad8">
      <self_collide>1</self_collide>
      <pose>0.12506683211155 0.22000000000000003 0.20455131111592997 0 3.14159265359 0</pose>
      <collision name="right_pad8_collision">
        <geometry>
        <mesh>
         <uri>
           file:///home/shankar/simu_ws/src/uhugv/track.stl 
         </uri>
        </mesh>
        </geometry>
      </collision>
      <visual name="right_pad8_visual">
        <geometry>
        <mesh>
         <uri>
           file:///home/shankar/simu_ws/src/uhugv/track.stl 
         </uri>
        </mesh>
        </geometry>
      </visual>
    </link>
    <joint name="right_pad_joint8" type="revolute">
      <pose>-0.0521 0 0 0 0 0</pose>
      <parent>right_pad8</parent>
      <child>right_pad9</child>
      <axis>
        <xyz>0 1 0</xyz>
      </axis>
    </joint>
    <link name="right_pad9">
      <self_collide>1</self_collide>
      <pose>0.020866832111550007 0.22000000000000003 0.20455131111592986 0 3.14159265359 0</pose>
      <collision name="right_pad9_collision">
        <geometry>
        <mesh>
         <uri>
           file:///home/shankar/simu_ws/src/uhugv/track.stl 
         </uri>
        </mesh>
        </geometry>
      </collision>
      <visual name="right_pad9_visual">
        <geometry>
        <mesh>
         <uri>
           file:///home/shankar/simu_ws/src/uhugv/track.stl 
         </uri>
        </mesh>
        </geometry>
      </visual>
    </link>
    <joint name="right_pad_joint9" type="revolute">
      <pose>-0.0521 0 0 0 0 0</pose>
      <parent>right_pad9</parent>
      <child>right_pad10</child>
      <axis>
        <xyz>0 1 0</xyz>
      </axis>
    </joint>
    <link name="right_pad10">
      <self_collide>1</self_collide>
      <pose>-0.08333316788845 0.22000000000000003 0.20455131111592975 0 3.14159265359 0</pose>
      <collision name="right_pad10_collision">
        <geometry>
        <mesh>
         <uri>
           file:///home/shankar/simu_ws/src/uhugv/track.stl 
         </uri>
        </mesh>
        </geometry>
      </collision>
      <visual name="right_pad10_visual">
        <geometry>
        <mesh>
         <uri>
           file:///home/shankar/simu_ws/src/uhugv/track.stl 
         </uri>
        </mesh>
        </geometry>
      </visual>
    </link>
    <joint name="right_pad_joint10" type="revolute">
      <pose>-0.0521 0 0 0 0 0</pose>
      <parent>right_pad10</parent>
      <child>right_pad11</child>
      <axis>
        <xyz>0 1 0</xyz>
      </axis>
    </joint>
    <link name="right_pad11">
      <self_collide>1</self_collide>
      <pose>-0.18753316788844998 0.22000000000000003 0.20455131111592964 0 3.14159265359 0</pose>
      <collision name="right_pad11_collision">
        <geometry>
        <mesh>
         <uri>
           file:///home/shankar/simu_ws/src/uhugv/track.stl 
         </uri>
        </mesh>
        </geometry>
      </collision>
      <visual name="right_pad11_visual">
        <geometry>
        <mesh>
         <uri>
           file:///home/shankar/simu_ws/src/uhugv/track.stl 
         </uri>
        </mesh>
        </geometry>
      </visual>
    </link>
    <joint name="right_pad_joint11" type="revolute">
      <pose>-0.0521 0 0 0 0 0</pose>
      <parent>right_pad11</parent>
      <child>right_pad12</child>
      <axis>
        <xyz>0 1 0</xyz>
      </axis>
    </joint>
    <link name="right_pad12">
      <self_collide>1</self_collide>
      <pose>-0.29173316788845 0.22000000000000003 0.20455131111592953 0 3.14159265359 0</pose>
      <collision name="right_pad12_collision">
        <geometry>
        <mesh>
         <uri>
           file:///home/shankar/simu_ws/src/uhugv/track.stl 
         </uri>
        </mesh>
        </geometry>
      </collision>
      <visual name="right_pad12_visual">
        <geometry>
        <mesh>
         <uri>
           file:///home/shankar/simu_ws/src/uhugv/track.stl 
         </uri>
        </mesh>
        </geometry>
      </visual>
    </link>
    <joint name="right_pad_joint12" type="revolute">
      <pose>-0.0521 0 0 0 0 0</pose>
      <parent>right_pad12</parent>
      <child>right_pad13</child>
      <axis>
        <xyz>0 1 0</xyz>
      </axis>
    </joint>
    <link name="right_pad13">
      <self_collide>1</self_collide>
      <pose>-0.3728861138387657 0.22000000000000003 0.16130392585845946 0 2.16233404597 0</pose>
      <collision name="right_pad13_collision">
        <geometry>
        <mesh>
         <uri>
           file:///home/shankar/simu_ws/src/uhugv/track.stl 
         </uri>
        </mesh>
        </geometry>
      </collision>
      <visual name="right_pad13_visual">
        <geometry>
        <mesh>
         <uri>
           file:///home/shankar/simu_ws/src/uhugv/track.stl 
         </uri>
        </mesh>
        </geometry>
      </visual>
    </link>
    <joint name="right_pad_joint13" type="revolute">
      <pose>-0.0521 0 0 0 0 0</pose>
      <parent>right_pad13</parent>
      <child>right_pad14</child>
      <axis>
        <xyz>0 1 0</xyz>
      </axis>
    </joint>
    <link name="right_pad14">
      <self_collide>1</self_collide>
      <pose>-0.38224111999606664 0.22000000000000003 0.0698237595500199 0 1.18307543836 0</pose>
      <collision name="right_pad14_collision">
        <geometry>
        <mesh>
         <uri>
           file:///home/shankar/simu_ws/src/uhugv/track.stl 
         </uri>
        </mesh>
        </geometry>
      </collision>
      <visual name="right_pad14_visual">
        <geometry>
        <mesh>
         <uri>
           file:///home/shankar/simu_ws/src/uhugv/track.stl 
         </uri>
        </mesh>
        </geometry>
      </visual>
    </link>
    <joint name="right_pad_joint14" type="revolute">
      <pose>-0.0521 0 0 0 0 0</pose>
      <parent>right_pad14</parent>
      <child>right_pad15</child>
      <axis>
        <xyz>0 1 0</xyz>
      </axis>
    </joint>
    <link name="right_pad15">
      <self_collide>1</self_collide>
      <pose>-0.3115215901015258 0.22000000000000003 0.011045489249524927 0 0.203816830743 0</pose>
      <collision name="right_pad15_collision">
        <geometry>
        <mesh>
         <uri>
           file:///home/shankar/simu_ws/src/uhugv/track.stl 
         </uri>
        </mesh>
        </geometry>
      </collision>
      <visual name="right_pad15_visual">
        <geometry>
        <mesh>
         <uri>
           file:///home/shankar/simu_ws/src/uhugv/track.stl 
         </uri>
        </mesh>
        </geometry>
      </visual>
    </link>
    <joint name="right_pad_joint15" type="revolute">
      <pose>-0.0521 0 0 0 0 0</pose>
      <parent>right_pad15</parent>
      <child>right_pad16</child>
      <axis>
        <xyz>0 1 0</xyz>
      </axis>
    </joint>
    <link name="right_pad16">
      <self_collide>1</self_collide>
      <pose>-0.20839999999999975 0.22000000000000003 0.0004999999999995893 0 -1.68924555736e-15 0</pose>
      <collision name="right_pad16_collision">
        <geometry>
        <mesh>
         <uri>
           file:///home/shankar/simu_ws/src/uhugv/track.stl 
         </uri>
        </mesh>
        </geometry>
      </collision>
      <visual name="right_pad16_visual">
        <geometry>
        <mesh>
         <uri>
           file:///home/shankar/simu_ws/src/uhugv/track.stl 
         </uri>
        </mesh>
        </geometry>
      </visual>
    </link>
    <joint name="right_pad_joint16" type="revolute">
      <pose>-0.0521 0 0 0 0 0</pose>
      <parent>right_pad16</parent>
      <child>right_pad17</child>
      <axis>
        <xyz>0 1 0</xyz>
      </axis>
    </joint>
    <link name="right_pad17">
      <self_collide>1</self_collide>
      <pose>-0.10419999999999975 0.22000000000000003 0.0004999999999997653 0 -1.68924555736e-15 0</pose>
      <collision name="right_pad17_collision">
        <geometry>
        <mesh>
         <uri>
           file:///home/shankar/simu_ws/src/uhugv/track.stl 
         </uri>
        </mesh>
        </geometry>
      </collision>
      <visual name="right_pad17_visual">
        <geometry>
        <mesh>
         <uri>
           file:///home/shankar/simu_ws/src/uhugv/track.stl 
         </uri>
        </mesh>
        </geometry>
      </visual>
    </link>
    <joint name="right_pad_joint17" type="revolute">
      <pose>-0.0521 0 0 0 0 0</pose>
      <parent>right_pad17</parent>
      <child>right_pad1</child>
      <axis>
        <xyz>0 1 0</xyz>
      </axis>
    </joint>
    <link name="left_pad1">
      <self_collide>1</self_collide>
      <pose>0.1042 -0.22000000000000003 0.0005 0 0.0 0</pose>
      <collision name="left_pad1_collision">
        <geometry>
        <mesh>
         <uri>
           file:///home/shankar/simu_ws/src/uhugv/track.stl 
         </uri>
        </mesh>
        </geometry>
      </collision>
      <visual name="left_pad1_visual">
        <geometry>
        <mesh>
         <uri>
           file:///home/shankar/simu_ws/src/uhugv/track.stl 
         </uri>
        </mesh>
        </geometry>
      </visual>
    </link>
    <joint name="left_pad_joint1" type="revolute">
      <pose>-0.0521 0 0 0 0 0</pose>
      <parent>left_pad1</parent>
      <child>left_pad2</child>
      <axis>
        <xyz>0 1 0</xyz>
      </axis>
    </joint>
    <link name="left_pad2">
      <self_collide>1</self_collide>
      <pose>0.2084 -0.22000000000000003 0.0005 0 0.0 0</pose>
      <collision name="left_pad2_collision">
        <geometry>
        <mesh>
         <uri>
           file:///home/shankar/simu_ws/src/uhugv/track.stl 
         </uri>
        </mesh>
        </geometry>
      </collision>
      <visual name="left_pad2_visual">
        <geometry>
        <mesh>
         <uri>
           file:///home/shankar/simu_ws/src/uhugv/track.stl 
         </uri>
        </mesh>
        </geometry>
      </visual>
    </link>
    <joint name="left_pad_joint2" type="revolute">
      <pose>-0.0521 0 0 0 0 0</pose>
      <parent>left_pad2</parent>
      <child>left_pad3</child>
      <axis>
        <xyz>0 1 0</xyz>
      </axis>
    </joint>
    <link name="left_pad3">
      <self_collide>1</self_collide>
      <pose>0.3126 -0.22000000000000003 0.0005 0 0.0 0</pose>
      <collision name="left_pad3_collision">
        <geometry>
        <mesh>
         <uri>
           file:///home/shankar/simu_ws/src/uhugv/track.stl 
         </uri>
        </mesh>
        </geometry>
      </collision>
      <visual name="left_pad3_visual">
        <geometry>
        <mesh>
         <uri>
           file:///home/shankar/simu_ws/src/uhugv/track.stl 
         </uri>
        </mesh>
        </geometry>
      </visual>
    </link>
    <joint name="left_pad_joint3" type="revolute">
      <pose>-0.0521 0 0 0 0 0</pose>
      <parent>left_pad3</parent>
      <child>left_pad4</child>
      <axis>
        <xyz>0 1 0</xyz>
      </axis>
    </joint>
    <link name="left_pad4">
      <self_collide>1</self_collide>
      <pose>0.39375294595031574 -0.22000000000000003 0.04374738525746999 0 -0.979258607616 0</pose>
      <collision name="left_pad4_collision">
        <geometry>
        <mesh>
         <uri>
           file:///home/shankar/simu_ws/src/uhugv/track.stl 
         </uri>
        </mesh>
        </geometry>
      </collision>
      <visual name="left_pad4_visual">
        <geometry>
        <mesh>
         <uri>
           file:///home/shankar/simu_ws/src/uhugv/track.stl 
         </uri>
        </mesh>
        </geometry>
      </visual>
    </link>
    <joint name="left_pad_joint4" type="revolute">
      <pose>-0.0521 0 0 0 0 0</pose>
      <parent>left_pad4</parent>
      <child>left_pad5</child>
      <axis>
        <xyz>0 1 0</xyz>
      </axis>
    </joint>
    <link name="left_pad5">
      <self_collide>1</self_collide>
      <pose>0.4031079521076168 -0.22000000000000003 0.13522755156590954 0 -1.95851721523 0</pose>
      <collision name="left_pad5_collision">
        <geometry>
        <mesh>
         <uri>
           file:///home/shankar/simu_ws/src/uhugv/track.stl 
         </uri>
        </mesh>
        </geometry>
      </collision>
      <visual name="left_pad5_visual">
        <geometry>
        <mesh>
         <uri>
           file:///home/shankar/simu_ws/src/uhugv/track.stl 
         </uri>
        </mesh>
        </geometry>
      </visual>
    </link>
    <joint name="left_pad_joint5" type="revolute">
      <pose>-0.0521 0 0 0 0 0</pose>
      <parent>left_pad5</parent>
      <child>left_pad6</child>
      <axis>
        <xyz>0 1 0</xyz>
      </axis>
    </joint>
    <link name="left_pad6">
      <self_collide>1</self_collide>
      <pose>0.3323884222130761 -0.22000000000000003 0.19400582186640458 0 -2.93777582285 0</pose>
      <collision name="left_pad6_collision">
        <geometry>
        <mesh>
         <uri>
           file:///home/shankar/simu_ws/src/uhugv/track.stl 
         </uri>
        </mesh>
        </geometry>
      </collision>
      <visual name="left_pad6_visual">
        <geometry>
        <mesh>
         <uri>
           file:///home/shankar/simu_ws/src/uhugv/track.stl 
         </uri>
        </mesh>
        </geometry>
      </visual>
    </link>
    <joint name="left_pad_joint6" type="revolute">
      <pose>-0.0521 0 0 0 0 0</pose>
      <parent>left_pad6</parent>
      <child>left_pad7</child>
      <axis>
        <xyz>0 1 0</xyz>
      </axis>
    </joint>
    <link name="left_pad7">
      <self_collide>1</self_collide>
      <pose>0.22926683211155 -0.22000000000000003 0.20455131111593003 0 3.14159265359 0</pose>
      <collision name="left_pad7_collision">
        <geometry>
        <mesh>
         <uri>
           file:///home/shankar/simu_ws/src/uhugv/track.stl 
         </uri>
        </mesh>
        </geometry>
      </collision>
      <visual name="left_pad7_visual">
        <geometry>
        <mesh>
         <uri>
           file:///home/shankar/simu_ws/src/uhugv/track.stl 
         </uri>
        </mesh>
        </geometry>
      </visual>
    </link>
    <joint name="left_pad_joint7" type="revolute">
      <pose>-0.0521 0 0 0 0 0</pose>
      <parent>left_pad7</parent>
      <child>left_pad8</child>
      <axis>
        <xyz>0 1 0</xyz>
      </axis>
    </joint>
    <link name="left_pad8">
      <self_collide>1</self_collide>
      <pose>0.12506683211155 -0.22000000000000003 0.20455131111592997 0 3.14159265359 0</pose>
      <collision name="left_pad8_collision">
        <geometry>
        <mesh>
         <uri>
           file:///home/shankar/simu_ws/src/uhugv/track.stl 
         </uri>
        </mesh>
        </geometry>
      </collision>
      <visual name="left_pad8_visual">
        <geometry>
        <mesh>
         <uri>
           file:///home/shankar/simu_ws/src/uhugv/track.stl 
         </uri>
        </mesh>
        </geometry>
      </visual>
    </link>
    <joint name="left_pad_joint8" type="revolute">
      <pose>-0.0521 0 0 0 0 0</pose>
      <parent>left_pad8</parent>
      <child>left_pad9</child>
      <axis>
        <xyz>0 1 0</xyz>
      </axis>
    </joint>
    <link name="left_pad9">
      <self_collide>1</self_collide>
      <pose>0.020866832111550007 -0.22000000000000003 0.20455131111592986 0 3.14159265359 0</pose>
      <collision name="left_pad9_collision">
        <geometry>
        <mesh>
         <uri>
           file:///home/shankar/simu_ws/src/uhugv/track.stl 
         </uri>
        </mesh>
        </geometry>
      </collision>
      <visual name="left_pad9_visual">
        <geometry>
        <mesh>
         <uri>
           file:///home/shankar/simu_ws/src/uhugv/track.stl 
         </uri>
        </mesh>
        </geometry>
      </visual>
    </link>
    <joint name="left_pad_joint9" type="revolute">
      <pose>-0.0521 0 0 0 0 0</pose>
      <parent>left_pad9</parent>
      <child>left_pad10</child>
      <axis>
        <xyz>0 1 0</xyz>
      </axis>
    </joint>
    <link name="left_pad10">
      <self_collide>1</self_collide>
      <pose>-0.08333316788845 -0.22000000000000003 0.20455131111592975 0 3.14159265359 0</pose>
      <collision name="left_pad10_collision">
        <geometry>
        <mesh>
         <uri>
           file:///home/shankar/simu_ws/src/uhugv/track.stl 
         </uri>
        </mesh>
        </geometry>
      </collision>
      <visual name="left_pad10_visual">
        <geometry>
        <mesh>
         <uri>
           file:///home/shankar/simu_ws/src/uhugv/track.stl 
         </uri>
        </mesh>
        </geometry>
      </visual>
    </link>
    <joint name="left_pad_joint10" type="revolute">
      <pose>-0.0521 0 0 0 0 0</pose>
      <parent>left_pad10</parent>
      <child>left_pad11</child>
      <axis>
        <xyz>0 1 0</xyz>
      </axis>
    </joint>
    <link name="left_pad11">
      <self_collide>1</self_collide>
      <pose>-0.18753316788844998 -0.22000000000000003 0.20455131111592964 0 3.14159265359 0</pose>
      <collision name="left_pad11_collision">
        <geometry>
        <mesh>
         <uri>
           file:///home/shankar/simu_ws/src/uhugv/track.stl 
         </uri>
        </mesh>
        </geometry>
      </collision>
      <visual name="left_pad11_visual">
        <geometry>
        <mesh>
         <uri>
           file:///home/shankar/simu_ws/src/uhugv/track.stl 
         </uri>
        </mesh>
        </geometry>
      </visual>
    </link>
    <joint name="left_pad_joint11" type="revolute">
      <pose>-0.0521 0 0 0 0 0</pose>
      <parent>left_pad11</parent>
      <child>left_pad12</child>
      <axis>
        <xyz>0 1 0</xyz>
      </axis>
    </joint>
    <link name="left_pad12">
      <self_collide>1</self_collide>
      <pose>-0.29173316788845 -0.22000000000000003 0.20455131111592953 0 3.14159265359 0</pose>
      <collision name="left_pad12_collision">
        <geometry>
        <mesh>
         <uri>
           file:///home/shankar/simu_ws/src/uhugv/track.stl 
         </uri>
        </mesh>
        </geometry>
      </collision>
      <visual name="left_pad12_visual">
        <geometry>
        <mesh>
         <uri>
           file:///home/shankar/simu_ws/src/uhugv/track.stl 
         </uri>
        </mesh>
        </geometry>
      </visual>
    </link>
    <joint name="left_pad_joint12" type="revolute">
      <pose>-0.0521 0 0 0 0 0</pose>
      <parent>left_pad12</parent>
      <child>left_pad13</child>
      <axis>
        <xyz>0 1 0</xyz>
      </axis>
    </joint>
    <link name="left_pad13">
      <self_collide>1</self_collide>
      <pose>-0.3728861138387657 -0.22000000000000003 0.16130392585845946 0 2.16233404597 0</pose>
      <collision name="left_pad13_collision">
        <geometry>
        <mesh>
         <uri>
           file:///home/shankar/simu_ws/src/uhugv/track.stl 
         </uri>
        </mesh>
        </geometry>
      </collision>
      <visual name="left_pad13_visual">
        <geometry>
        <mesh>
         <uri>
           file:///home/shankar/simu_ws/src/uhugv/track.stl 
         </uri>
        </mesh>
        </geometry>
      </visual>
    </link>
    <joint name="left_pad_joint13" type="revolute">
      <pose>-0.0521 0 0 0 0 0</pose>
      <parent>left_pad13</parent>
      <child>left_pad14</child>
      <axis>
        <xyz>0 1 0</xyz>
      </axis>
    </joint>
    <link name="left_pad14">
      <self_collide>1</self_collide>
      <pose>-0.38224111999606664 -0.22000000000000003 0.0698237595500199 0 1.18307543836 0</pose>
      <collision name="left_pad14_collision">
        <geometry>
        <mesh>
         <uri>
           file:///home/shankar/simu_ws/src/uhugv/track.stl 
         </uri>
        </mesh>
        </geometry>
      </collision>
      <visual name="left_pad14_visual">
        <geometry>
        <mesh>
         <uri>
           file:///home/shankar/simu_ws/src/uhugv/track.stl 
         </uri>
        </mesh>
        </geometry>
      </visual>
    </link>
    <joint name="left_pad_joint14" type="revolute">
      <pose>-0.0521 0 0 0 0 0</pose>
      <parent>left_pad14</parent>
      <child>left_pad15</child>
      <axis>
        <xyz>0 1 0</xyz>
      </axis>
    </joint>
    <link name="left_pad15">
      <self_collide>1</self_collide>
      <pose>-0.3115215901015258 -0.22000000000000003 0.011045489249524927 0 0.203816830743 0</pose>
      <collision name="left_pad15_collision">
        <geometry>
        <mesh>
         <uri>
           file:///home/shankar/simu_ws/src/uhugv/track.stl 
         </uri>
        </mesh>
        </geometry>
      </collision>
      <visual name="left_pad15_visual">
        <geometry>
        <mesh>
         <uri>
           file:///home/shankar/simu_ws/src/uhugv/track.stl 
         </uri>
        </mesh>
        </geometry>
      </visual>
    </link>
    <joint name="left_pad_joint15" type="revolute">
      <pose>-0.0521 0 0 0 0 0</pose>
      <parent>left_pad15</parent>
      <child>left_pad16</child>
      <axis>
        <xyz>0 1 0</xyz>
      </axis>
    </joint>
    <link name="left_pad16">
      <self_collide>1</self_collide>
      <pose>-0.20839999999999975 -0.22000000000000003 0.0004999999999995893 0 -1.68924555736e-15 0</pose>
      <collision name="left_pad16_collision">
        <geometry>
        <mesh>
         <uri>
           file:///home/shankar/simu_ws/src/uhugv/track.stl 
         </uri>
        </mesh>
        </geometry>
      </collision>
      <visual name="left_pad16_visual">
        <geometry>
        <mesh>
         <uri>
           file:///home/shankar/simu_ws/src/uhugv/track.stl 
         </uri>
        </mesh>
        </geometry>
      </visual>
    </link>
    <joint name="left_pad_joint16" type="revolute">
      <pose>-0.0521 0 0 0 0 0</pose>
      <parent>left_pad16</parent>
      <child>left_pad17</child>
      <axis>
        <xyz>0 1 0</xyz>
      </axis>
    </joint>
    <link name="left_pad17">
      <self_collide>1</self_collide>
      <pose>-0.10419999999999975 -0.22000000000000003 0.0004999999999997653 0 -1.68924555736e-15 0</pose>
      <collision name="left_pad17_collision">
        <geometry>
        <mesh>
         <uri>
           file:///home/shankar/simu_ws/src/uhugv/track.stl 
         </uri>
        </mesh>
        </geometry>
      </collision>
      <visual name="left_pad17_visual">
        <geometry>
        <mesh>
         <uri>
           file:///home/shankar/simu_ws/src/uhugv/track.stl 
         </uri>
        </mesh>
        </geometry>
      </visual>
    </link>
    <joint name="left_pad_joint17" type="revolute">
      <pose>-0.0521 0 0 0 0 0</pose>
      <parent>left_pad17</parent>
      <child>left_pad1</child>
      <axis>
        <xyz>0 1 0</xyz>
      </axis>
    </joint>

 
<plugin name="skid_steer_drive_controller" filename="libgazebo_ros_skid_steer_drive.so">
    <updateRate>100.0</updateRate>
    <robotNamespace>/</robotNamespace>
    <leftFrontJoint>drum_joint1</leftFrontJoint>
    <rightFrontJoint>drum_joint2</rightFrontJoint>
    <leftRearJoint>drum_joint3</leftRearJoint>
    <rightRearJoint>drum_joint4</rightRearJoint>
    <wheelSeparation>0.340</wheelSeparation>
    <wheelDiameter>0.14</wheelDiameter>
    <robotBaseFrame>base_link</robotBaseFrame>
    <torque>20</torque>
    <topicName>cmd_vel</topicName>
    <broadcastTF>false</broadcastTF>
</plugin>
  </model>
</world>
</sdf>

