<?xml version="1.0" encoding="utf-8"?>
<robot name="track">
<gazebo>
<plugin name="gazebo_ros_control" filename="libgazebo_ros_control.so">
<robotNamespace>/track</robotNamespace>
</plugin>
</gazebo>

<gazebo>
<plugin name="buyoancy_plugin" filename="libBuoyancyPlugin.so">
<fluid_density>15.284252</fluid_density>
<link name="base_link" />
</plugin>
</gazebo>
<link name="base_link">
<inertial>
<origin
xyz="0.0 0.0 0.14"
rpy="0 0 0" />
<mass
value="1.0" />
<inertia
ixx="0.03862166"
ixy="0.0"
ixz="0.0"
iyy="0.0277856"
iyz="0.0"
izz="0.0608866" />
</inertial>
<visual>
<origin xyz="0.0 0.0 0.14" rpy="0.0 0.0 0.0" />
<geometry>
<mesh filename="package://uhugv/uhugv.dae" />    
</geometry>    
</visual>
<collision>
<origin xyz="0.0 0.0 0.14" rpy="0.0 0.0 0.0" />
<geometry>
<box size="0.548 0.656 0.182"/>
</geometry>  
</collision>
</link>
<gazebo reference="base_link"/>
<link name='servoL_mount_1'>
<inertial>
<origin
xyz="0.0 0.1 0.0"
rpy="0 0 0" />
<mass
value="0.2" />
<inertia
ixx="0.0006683"
ixy="0.0"
ixz="0.0"
iyy="0.00016833"
iyz="0.0"
izz="0.00083333" />
</inertial>
<visual>
<origin xyz="0.0 0.1 0.0" rpy="0.0 0.0 0.0" />
<geometry>
<mesh filename="package://uhugv/servo.dae" />    
</geometry>    
</visual>
<collision>
<origin xyz="0.0 0.1 0.0" rpy="0.0 0.0 0.0" />
<geometry>
<box size="0.1 0.2 0.01"/>
</geometry>  
</collision>
</link>
<gazebo reference="servoL_mount_1"/>
<joint name="servoL_1" type="revolute">
<origin xyz="0.21 0.31 0.14" rpy="0 0 0" />
<parent link="base_link"/>
<child link="servoL_mount_1" />
<axis xyz="1.0 0.0 0.0"/>
<dynamics damping="0.1" friction="0.1"/>
<limit effort="1.0" velocity="100" lower="-1.57" upper="1.57" />
</joint>
<link name='servoL_mount_2'>
<inertial>
<origin
xyz="0.0 0.1 0.0"
rpy="0 0 0" />
<mass
value="0.2" />
<inertia
ixx="0.0006683"
ixy="0.0"
ixz="0.0"
iyy="0.00016833"
iyz="0.0"
izz="0.00083333" />
</inertial>
<visual>
<origin xyz="0.0 0.1 0.0" rpy="0.0 0.0 0.0" />
<geometry>
<mesh filename="package://uhugv/servo.dae" />    
</geometry>    
</visual>
<collision>
<origin xyz="0.0 0.1 0.0" rpy="0.0 0.0 0.0" />
<geometry>
<box size="0.1 0.2 0.01"/>
</geometry>  
</collision>
</link>
<gazebo reference="servoL_mount_2"/>
<joint name="servoL_2" type="revolute">
<origin xyz="0.11 0.31 0.14" rpy="0 0 0" />
<parent link="base_link"/>
<child link="servoL_mount_2" />
<axis xyz="1.0 0.0 0.0"/>
<dynamics damping="0.1" friction="0.1"/>
<limit effort="1.0" velocity="100" lower="-1.57" upper="1.57" />
</joint>
<link name='servoL_mount_3'>
<inertial>
<origin
xyz="0.0 0.1 0.0"
rpy="0 0 0" />
<mass
value="0.2" />
<inertia
ixx="0.0006683"
ixy="0.0"
ixz="0.0"
iyy="0.00016833"
iyz="0.0"
izz="0.00083333" />
</inertial>
<visual>
<origin xyz="0.0 0.1 0.0" rpy="0.0 0.0 0.0" />
<geometry>
<mesh filename="package://uhugv/servo.dae" />    
</geometry>    
</visual>
<collision>
<origin xyz="0.0 0.1 0.0" rpy="0.0 0.0 0.0" />
<geometry>
<box size="0.1 0.2 0.01"/>
</geometry>  
</collision>
</link>
<gazebo reference="servoL_mount_3"/>
<joint name="servoL_3" type="revolute">
<origin xyz="0.0 0.31 0.14" rpy="0 0 0" />
<parent link="base_link"/>
<child link="servoL_mount_3" />
<axis xyz="1.0 0.0 0.0"/>
<dynamics damping="0.1" friction="0.1"/>
<limit effort="1.0" velocity="100" lower="-1.57" upper="1.57" />
</joint>
<link name='servoL_mount_4'>
<inertial>
<origin
xyz="0.0 0.1 0.0"
rpy="0 0 0" />
<mass
value="0.2" />
<inertia
ixx="0.0006683"
ixy="0.0"
ixz="0.0"
iyy="0.00016833"
iyz="0.0"
izz="0.00083333" />
</inertial>
<visual>
<origin xyz="0.0 0.1 0.0" rpy="0.0 0.0 0.0" />
<geometry>
<mesh filename="package://uhugv/servo.dae" />    
</geometry>    
</visual>
<collision>
<origin xyz="0.0 0.1 0.0" rpy="0.0 0.0 0.0" />
<geometry>
<box size="0.1 0.2 0.01"/>
</geometry>  
</collision>
</link>
<gazebo reference="servoL_mount_4"/>
<joint name="servoL_4" type="revolute">
<origin xyz="-0.11 0.31 0.14" rpy="0 0 0" />
<parent link="base_link"/>
<child link="servoL_mount_4" />
<axis xyz="1.0 0.0 0.0"/>
<dynamics damping="0.1" friction="0.1"/>
<limit effort="1.0" velocity="100" lower="-1.57" upper="1.57" />
</joint>

<link name='servoR_mount_1'>
<inertial>
<origin
xyz="0.0 -0.1 0.0"
rpy="0 0 0" />
<mass
value="0.2" />
<inertia
ixx="0.0006683"
ixy="0.0"
ixz="0.0"
iyy="0.00016833"
iyz="0.0"
izz="0.00083333" />
</inertial>
<visual>
<origin xyz="0.0 -0.1 0.0" rpy="0.0 0.0 0.0" />
<geometry>
<mesh filename="package://uhugv/servo.dae" />    
</geometry>    
</visual>
<collision>
<origin xyz="0.0 -0.1 0.0" rpy="0.0 0.0 0.0" />
<geometry>
<box size="0.1 0.2 0.01"/>
</geometry>  
</collision>
</link>
<gazebo reference="servoR_mount_1"/>
<joint name="servoR_1" type="revolute">
<origin xyz="0.21 -0.31 0.14" rpy="0 0 0" />
<parent link="base_link"/>
<child link="servoR_mount_1" />
<axis xyz="1.0 0.0 0.0"/>
<dynamics damping="0.1" friction="0.1"/>
<limit effort="1.0" velocity="100" lower="-1.57" upper="1.57" />
</joint>
<link name='servoR_mount_2'>
<inertial>
<origin
xyz="0.0 -0.1 0.0"
rpy="0 0 0" />
<mass
value="0.2" />
<inertia
ixx="0.0006683"
ixy="0.0"
ixz="0.0"
iyy="0.00016833"
iyz="0.0"
izz="0.00083333" />
</inertial>
<visual>
<origin xyz="0.0 -0.1 0.0" rpy="0.0 0.0 0.0" />
<geometry>
<mesh filename="package://uhugv/servo.dae" />    
</geometry>    
</visual>
<collision>
<origin xyz="0.0 -0.1 0.0" rpy="0.0 0.0 0.0" />
<geometry>
<box size="0.1 0.2 0.01"/>
</geometry>  
</collision>
</link>
<gazebo reference="servoR_mount_2"/>
<joint name="servoR_2" type="revolute">
<origin xyz="0.11 -0.31 0.14" rpy="0 0 0" />
<parent link="base_link"/>
<child link="servoR_mount_2" />
<axis xyz="1.0 0.0 0.0"/>
<dynamics damping="0.1" friction="0.1"/>
<limit effort="1.0" velocity="100" lower="-1.57" upper="1.57" />
</joint>
<link name='servoR_mount_3'>
<inertial>
<origin
xyz="0 -0.1 0"
rpy="0 0 0" />
<mass
value="0.2" />
<inertia
ixx="0.0006683"
ixy="0.0"
ixz="0.0"
iyy="0.00016833"
iyz="0.0"
izz="0.00083333" />
</inertial>
<visual>
<origin xyz="0 -0.1 0" rpy="0.0 0.0 0.0" />
<geometry>
<mesh filename="package://uhugv/servo.dae" />    
</geometry>    
</visual>
<collision>
<origin xyz="0 -0.1 0" rpy="0.0 0.0 0.0" />
<geometry>
<box size="0.1 0.2 0.01"/>
</geometry>  
</collision>
</link>
<gazebo reference="servoR_mount_3"/>
<joint name="servoR_3" type="revolute">
<origin xyz="0.0 -0.31 0.14" rpy="0 0 0" />
<parent link="base_link"/>
<child link="servoR_mount_3" />
<axis xyz="1.0 0.0 0.0"/>
<dynamics damping="0.1" friction="0.1"/>
<limit effort="1.0" velocity="100" lower="-1.57" upper="1.57" />
</joint>
<link name='servoR_mount_4'>
<inertial>
<origin
xyz="0.0 -0.1 0.0"
rpy="0 0 0" />
<mass
value="0.2" />
<inertia
ixx="0.0006683"
ixy="0.0"
ixz="0.0"
iyy="0.00016833"
iyz="0.0"
izz="0.00083333" />
</inertial>
<visual>
<origin xyz="0.0 -0.1 0.0" rpy="0.0 0.0 0.0" />
<geometry>
<mesh filename="package://uhugv/servo.dae" />    
</geometry>    
</visual>
<collision>
<origin xyz="0.0 -0.1 0.0" rpy="0.0 0.0 0.0" />
<geometry>
<box size="0.1 0.2 0.01"/>
</geometry>  
</collision>
</link>
<gazebo reference="servoR_mount_4"/>
<joint name="servoR_4" type="revolute">
<origin xyz="-0.11 -0.31 0.14" rpy="0 0 0" />
<parent link="base_link"/>
<child link="servoR_mount_4" />
<axis xyz="1.0 0.0 0.0"/>
<dynamics damping="0.1" friction="0.1"/>
    <limit effort="1.0" velocity="100" lower="-1.57" upper="1.57" />
    </joint>
  <transmission name="servoL1_trans">
    <type>transmission_interface/SimpleTransmission</type>
    <joint name="servoL_1">
      <hardwareInterface>hardware_interface/EffortJointInterface</hardwareInterface>
    </joint>
    <actuator name="servoL1_motor">
      <hardwareInterface>hardware_interface/EffortJointInterface</hardwareInterface>
      <mechanicalReduction>1</mechanicalReduction>
    </actuator>
  </transmission>
  <transmission name="servoL2_trans">
    <type>transmission_interface/SimpleTransmission</type>
    <joint name="servoL_2">
      <hardwareInterface>hardware_interface/EffortJointInterface</hardwareInterface>
    </joint>
    <actuator name="servoL2_motor">
      <hardwareInterface>hardware_interface/EffortJointInterface</hardwareInterface>
      <mechanicalReduction>1</mechanicalReduction>
    </actuator>
  </transmission>
  <transmission name="servoL3_trans">
    <type>transmission_interface/SimpleTransmission</type>
    <joint name="servoL_3">
      <hardwareInterface>hardware_interface/EffortJointInterface</hardwareInterface>
    </joint>
    <actuator name="servoL3_motor">
      <hardwareInterface>hardware_interface/EffortJointInterface</hardwareInterface>
      <mechanicalReduction>1</mechanicalReduction>
    </actuator>
  </transmission>
  <transmission name="servoL4_trans">
    <type>transmission_interface/SimpleTransmission</type>
    <joint name="servoL_4">
      <hardwareInterface>hardware_interface/EffortJointInterface</hardwareInterface>
    </joint>
    <actuator name="servoL4_motor">
      <hardwareInterface>hardware_interface/EffortJointInterface</hardwareInterface>
      <mechanicalReduction>1</mechanicalReduction>
    </actuator>
  </transmission>
  <transmission name="servoR1_trans">
    <type>transmission_interface/SimpleTransmission</type>
    <joint name="servoR_1">
      <hardwareInterface>hardware_interface/EffortJointInterface</hardwareInterface>
    </joint>
    <actuator name="servoR1_motor">
      <hardwareInterface>hardware_interface/EffortJointInterface</hardwareInterface>
      <mechanicalReduction>1</mechanicalReduction>
    </actuator>
  </transmission>
  <transmission name="servoR2_trans">
    <type>transmission_interface/SimpleTransmission</type>
    <joint name="servoR_2">
      <hardwareInterface>hardware_interface/EffortJointInterface</hardwareInterface>
    </joint>
    <actuator name="servoR2_motor">
      <hardwareInterface>hardware_interface/EffortJointInterface</hardwareInterface>
      <mechanicalReduction>1</mechanicalReduction>
    </actuator>
  </transmission>
  <transmission name="servoR3_trans">
    <type>transmission_interface/SimpleTransmission</type>
    <joint name="servoR_3">
      <hardwareInterface>hardware_interface/EffortJointInterface</hardwareInterface>
    </joint>
    <actuator name="servoR3_motor">
      <hardwareInterface>hardware_interface/EffortJointInterface</hardwareInterface>
      <mechanicalReduction>1</mechanicalReduction>
    </actuator>
  </transmission>
  <transmission name="servoR4_trans">
    <type>transmission_interface/SimpleTransmission</type>
    <joint name="servoR_4">
      <hardwareInterface>hardware_interface/EffortJointInterface</hardwareInterface>
    </joint>
    <actuator name="servoR4_motor">
      <hardwareInterface>hardware_interface/EffortJointInterface</hardwareInterface>
      <mechanicalReduction>1</mechanicalReduction>
    </actuator>
  </transmission>
</robot>